<testsuite name="TestAssetsNunit.One.ClassTwo" tests="6" failures="3" errors="0" skipped="2" time="0.0050339999999959705" >
<testcase classname="TestAssetsNunit.One.ClassTwo" name="TestOneOneIgnoredWithCause" outcome="NotExecuted" time="0.00006519999999810011"><skipped /></testcase>
<testcase classname="TestAssetsNunit.One.ClassTwo" name="TestOneTwoPass" outcome="Passed" time="0.0001599" />
<testcase classname="TestAssetsNunit.One.ClassTwo" name="TestOneOneIgnored" outcome="NotExecuted" time="0.0003621999999978698"><skipped /></testcase>
<testcase classname="TestAssetsNunit.One.ClassTwo" name="TestOneTwoFail" outcome="Failed" time="0.0009041"><failure>
MESSAGE:
  Expected: 1
  But was:  2

+++++++++++++++++++
STACK TRACE:
   at TestAssetsNunit.One.ClassTwo.TestOneTwoFail() in /TestAssetsNunit/TestAssetsNunit.cs:line 41
</failure></testcase>
<testcase classname="TestAssetsNunit.One.ClassTwo" name="TestOneTwoFailException" outcome="Failed" time="0.0028999"><failure>
MESSAGE:
System.Exception : This is an exception message
+++++++++++++++++++
STACK TRACE:
   at TestAssetsNunit.One.ClassTwo.TestOneTwoFailException() in /TestAssetsNunit/TestAssetsNunit.cs:line 51</failure></testcase>
<testcase classname="TestAssetsNunit.One.ClassTwo" name="TestOneTwoFailMessage" outcome="Failed" time="0.0006427"><failure>
MESSAGE:
  This is a failure message
  Expected: 1
  But was:  2

+++++++++++++++++++
STACK TRACE:
   at TestAssetsNunit.One.ClassTwo.TestOneTwoFailMessage() in /TestAssetsNunit/TestAssetsNunit.cs:line 46
</failure></testcase>
</testsuite>