<testsuite name="TestAssetsNunit.One.ClassTwo" tests="6" failures="3" errors="0" skipped="2" time="0.0895039" >
<testcase classname="TestAssetsNunit.One.ClassTwo" name="TestOneOneIgnored" outcome="NotExecuted" time="0.000411"><skipped /></testcase>
<testcase classname="TestAssetsNunit.One.ClassTwo" name="TestOneTwoFail" outcome="Failed" time="0.08569"><failure>
MESSAGE:
  Expected: 1
  But was:  2

+++++++++++++++++++
STACK TRACE:
   at TestAssetsNunit.One.ClassTwo.TestOneTwoFail() in /home/runner/work/dotnet-test-split/dotnet-test-split/TestAssetsNunit/TestAssetsNunit.cs:line 41

1)    at TestAssetsNunit.One.ClassTwo.TestOneTwoFail() in /home/runner/work/dotnet-test-split/dotnet-test-split/TestAssetsNunit/TestAssetsNunit.cs:line 41

</failure></testcase>
<testcase classname="TestAssetsNunit.One.ClassTwo" name="TestOneTwoPass" outcome="Passed" time="0.0000699" />
<testcase classname="TestAssetsNunit.One.ClassTwo" name="TestOneTwoFailMessage" outcome="Failed" time="0.001027"><failure>
MESSAGE:
  This is a failure message
  Expected: 1
  But was:  2

+++++++++++++++++++
STACK TRACE:
   at TestAssetsNunit.One.ClassTwo.TestOneTwoFailMessage() in /home/runner/work/dotnet-test-split/dotnet-test-split/TestAssetsNunit/TestAssetsNunit.cs:line 46

1)    at TestAssetsNunit.One.ClassTwo.TestOneTwoFailMessage() in /home/runner/work/dotnet-test-split/dotnet-test-split/TestAssetsNunit/TestAssetsNunit.cs:line 46

</failure></testcase>
<testcase classname="TestAssetsNunit.One.ClassTwo" name="TestOneTwoFailException" outcome="Failed" time="0.002293"><failure>
MESSAGE:
System.Exception : This is an exception message
+++++++++++++++++++
STACK TRACE:
   at TestAssetsNunit.One.ClassTwo.TestOneTwoFailException() in /home/runner/work/dotnet-test-split/dotnet-test-split/TestAssetsNunit/TestAssetsNunit.cs:line 51
</failure></testcase>
<testcase classname="TestAssetsNunit.One.ClassTwo" name="TestOneOneIgnoredWithCause" outcome="NotExecuted" time="0.000013"><skipped /></testcase>
</testsuite>